2025-03-02 01:02:13,547 INFO    MainThread:39963 [wandb_init.py:setup_run_log_directory():647] Logging user logs to /home/ic41223/DA6401/Assignment_1/wandb/run-20250302_010213-lguv1seb/logs/debug.log
2025-03-02 01:02:13,547 INFO    MainThread:39963 [wandb_init.py:setup_run_log_directory():648] Logging internal logs to /home/ic41223/DA6401/Assignment_1/wandb/run-20250302_010213-lguv1seb/logs/debug-internal.log
2025-03-02 01:02:13,547 INFO    MainThread:39963 [wandb_init.py:init():761] calling init triggers
2025-03-02 01:02:13,547 INFO    MainThread:39963 [wandb_init.py:init():766] wandb.init called with sweep_config: {}
config: {'_wandb': {}}
2025-03-02 01:02:13,547 INFO    MainThread:39963 [wandb_init.py:init():776] wandb.init() called while a run is active
2025-03-02 01:02:13,548 ERROR   MainThread:39963 [util.py:get_module():249] Error importing optional module PIL.Image
Traceback (most recent call last):
  File "/home/ic41223/miniconda3/envs/DA6401/lib/python3.9/site-packages/wandb/util.py", line 215, in import_module_lazy
    return sys.modules[name]
KeyError: 'PIL.Image'

During handling of the above exception, another exception occurred:

Traceback (most recent call last):
  File "/home/ic41223/miniconda3/envs/DA6401/lib/python3.9/site-packages/wandb/util.py", line 244, in get_module
    return import_module_lazy(name)
  File "/home/ic41223/miniconda3/envs/DA6401/lib/python3.9/site-packages/wandb/util.py", line 217, in import_module_lazy
    spec = importlib.util.find_spec(name)
  File "/home/ic41223/miniconda3/envs/DA6401/lib/python3.9/importlib/util.py", line 94, in find_spec
    parent = __import__(parent_name, fromlist=['__path__'])
ModuleNotFoundError: No module named 'PIL'
2025-03-02 01:02:13,744 INFO    MainThread:39963 [jupyter.py:save_ipynb():386] not saving jupyter notebook
2025-03-02 01:02:13,745 INFO    MainThread:39963 [wandb_init.py:_pause_backend():564] pausing backend
